<sdf version='1.7'>
  <model name='turtlebot3_burger'>

    <link name="base_footprint"/>
    
    <link name='sim_base_link'>
      <inertial>
        <pose>-0.00429 0 0.015 0 -0 0</pose>
        <mass>0.944735</mass>
        <inertia>
          <ixx>0.00717896</ixx>
          <ixy>-1.22941e-05</ixy>
          <ixz>0.00057674</ixz>
          <iyy>0.00721804</iyy>
          <iyz>-5.01209e-06</iyz>
          <izz>0.00413858</izz>
        </inertia>
      </inertial>
      <collision name='base_footprint_fixed_joint_lump__base_link_collision'>
        <pose>-0.032 0 0.08 0 -0 0</pose>
        <geometry>
          <box>
            <size>0.14 0.14 0.143</size>
          </box>
        </geometry>
      </collision>
      <collision name='base_footprint_fixed_joint_lump__caster_back_link_collision_1'>
        <pose>-0.081 1e-06 0.005 -1.57 0 0</pose>
        <geometry>
          <box>
            <size>0.03 0.009 0.02</size>
          </box>
        </geometry>
      </collision>
      <collision name='base_footprint_fixed_joint_lump__base_scan_collision_2'>
        <pose>-0.017 0 0.1755 0 -0 0</pose>
        <geometry>
          <cylinder>
            <length>0.0315</length>
            <radius>0.055</radius>
          </cylinder>
        </geometry>
      </collision>
      <visual name='base_footprint_fixed_joint_lump__base_link_visual'>
        <pose>-0.032 0 0.01 0 -0 0</pose>
        <geometry>
          <mesh>
            <scale>0.001 0.001 0.001</scale>
            <uri>model://turtlebot3_description/meshes/bases/burger_base.stl</uri>
          </mesh>
        </geometry>
        <material>
          <diffuse> 0.145098039 0.156862745 0.164705882 1</diffuse>
          <ambient> 0.145098039 0.156862745 0.164705882 1</ambient>
          <specular>0.145098039 0.156862745 0.164705882 1</specular>
        </material>        
      </visual>
      <visual name='base_footprint_fixed_joint_lump__base_scan_visual_1'>
        <pose>-0.032 0 0.182 0 -0 0</pose>
        <geometry>
          <mesh>
            <scale>0.001 0.001 0.001</scale>
            <uri>model://turtlebot3_description/meshes/sensors/lds.stl</uri>
          </mesh>
        </geometry>
        <material>
          <diffuse> 0.145098039 0.156862745 0.164705882 1</diffuse>
          <ambient> 0.145098039 0.156862745 0.164705882 1</ambient>
          <specular>0.145098039 0.156862745 0.164705882 1</specular>
        </material>
      </visual>
    </link>

    <joint name="base_joint" type="fixed">
      <pose>0 0 0.01 0 0 0</pose>
      <parent>base_footprint</parent>
      <child>sim_base_link</child>
    </joint>

    <link name="imu_link">
      <sensor name="imu" type="imu">
        <always_on>1</always_on>
        <update_rate>200</update_rate>
        <visualize>true</visualize>
        <topic>sim/imu</topic>
        <ignition_frame_id>imu_link</ignition_frame_id>
        <imu>
          <angular_velocity>
            <x>
              <noise type="gaussian">
                <mean>0.0</mean>
                <stddev>2e-4</stddev>
              </noise>
            </x>
            <y>
              <noise type="gaussian">
                <mean>0.0</mean>
                <stddev>2e-4</stddev>
              </noise>
            </y>
            <z>
              <noise type="gaussian">
                <mean>0.0</mean>
                <stddev>2e-4</stddev>
              </noise>
            </z>
          </angular_velocity>
          <linear_acceleration>
            <x>
              <noise type="gaussian">
                <mean>0.0</mean>
                <stddev>1.7e-2</stddev>
              </noise>
            </x>
            <y>
              <noise type="gaussian">
                <mean>0.0</mean>
                <stddev>1.7e-2</stddev>
              </noise>
            </y>
            <z>
              <noise type="gaussian">
                <mean>0.0</mean>
                <stddev>1.7e-2</stddev>
              </noise>
            </z>
          </linear_acceleration>
        </imu>
      </sensor>
    </link>

    <joint name="imu_joint" type="fixed">
      <pose>-0.032 0 0.068 0 0 0</pose>
      <parent>sim_base_link</parent>
      <child>imu_link</child>
    </joint>

    <!-- LIDAR -->
    <link name="sim_base_scan">
      <inertial>
        <pose>-0.052 0 0.111 0 0 0</pose>
        <inertia>
          <ixx>0.001</ixx>
          <ixy>0</ixy>
          <ixz>0</ixz>
          <iyy>0.001</iyy>
          <iyz>0</iyz>
          <izz>0.001</izz>
        </inertia>
        <mass>0.114</mass>
      </inertial>
      <collision name="lidar_sensor_collision">
        <pose>-0.052 0 0.111 0 0 0</pose>
        <geometry>
          <cylinder>
            <radius>0.0508</radius>
            <length>0.055</length>
          </cylinder>
        </geometry>
      </collision>
      <visual name="lidar_sensor_visual">
        <pose>-0.064 0 0.121 0 0 0</pose>
        <geometry>
          <mesh>
            <uri>model://turtlebot3/meshes/lds.dae</uri>
            <scale>0.001 0.001 0.001</scale>
          </mesh>
        </geometry>
        <material>
          <diffuse> 0.145098039 0.156862745 0.164705882 1</diffuse>
          <ambient> 0.145098039 0.156862745 0.164705882 1</ambient>
          <specular>0.145098039 0.156862745 0.164705882 1</specular>
        </material>
      </visual>
      <sensor name="gpu_lidar" type="gpu_lidar">
        <pose>-0.064 0 0.121 0 0 0</pose>
        <topic>sim_scan</topic>
        <ignition_frame_id>sim_base_scan</ignition_frame_id>
        <update_rate>5</update_rate>
        <ray>
          <scan>
            <horizontal>
              <samples>360</samples>
              <resolution>1</resolution>
              <min_angle>0</min_angle>
              <max_angle>6.28</max_angle>
            </horizontal>
          </scan>
          <range>
            <min>0.120000</min>
            <max>20.0</max>
            <resolution>0.015000</resolution>
          </range>
          <noise>
            <type>gaussian</type>
            <mean>0.0</mean>
            <stddev>0.01</stddev>
          </noise>
        </ray>
        <always_on>true</always_on>
        <visualize>1</visualize>
      </sensor>
    </link>

    <joint name="lidar_joint" type="fixed">
      <pose>-0.064 0 0.121 0 0 0</pose>
      <parent>sim_base_link</parent>
      <child>sim_base_scan</child>
    </joint>

    <link name='wheel_left_link'>
      <pose relative_to='wheel_left_joint'>0 0 0 0 -0 0</pose>
      <inertial>
        <pose>0 0 0 0 -0 0</pose>
        <mass>0.0284989</mass>
        <inertia>
          <ixx>1.11756e-05</ixx>
          <ixy>-4.23698e-11</ixy>
          <ixz>-5.93817e-09</ixz>
          <iyy>1.11924e-05</iyy>
          <iyz>-1.44001e-11</iyz>
          <izz>2.07126e-05</izz>
        </inertia>
      </inertial>
      <collision name='wheel_left_link_collision'>
        <pose>0 0 0 0 -0 0</pose>
        <surface>
          <friction>
            <ode>
              <mu>1.0</mu>
              <mu2>1.0</mu2>
            </ode>
          </friction>
        </surface>
        <geometry>
          <cylinder>
            <length>0.018</length>
            <radius>0.033</radius>
          </cylinder>
        </geometry>
      </collision>
      <visual name='wheel_left_link_visual'>
        <pose>0 0 0 1.57 -0 0</pose>
        <geometry>
          <mesh>
            <scale>0.001 0.001 0.001</scale>
            <uri>model://turtlebot3_description/meshes/wheels/left_tire.stl</uri>
          </mesh>
        </geometry>
        <material>
          <diffuse> 0.145098039 0.156862745 0.164705882 1</diffuse>
          <ambient> 0.145098039 0.156862745 0.164705882 1</ambient>
          <specular>0.145098039 0.156862745 0.164705882 1</specular>
        </material>
      </visual>
    </link>

    <joint name='wheel_left_joint' type='revolute'>
      <pose relative_to='sim_base_link'>0 0.08 0.033 -1.57 0 0</pose>
      <parent>sim_base_link</parent>
      <child>wheel_left_link</child>
      <axis>
        <xyz>0 0 1</xyz>
        <limit>
          <lower>-1e+16</lower>
          <upper>1e+16</upper>
        </limit>
        <dynamics>
          <spring_reference>0</spring_reference>
          <spring_stiffness>0</spring_stiffness>
          <damping>0.7</damping>
          <friction>0.0</friction>
        </dynamics>
      </axis>
    </joint>

    <joint name='wheel_right_joint' type='revolute'>
      <pose relative_to='base_footprint'>0 -0.08 0.033 -1.57 0 0</pose>
      <parent>sim_base_link</parent>
      <child>wheel_right_link</child>
      <axis>
        <xyz>0 0 1</xyz>
        <limit>
          <lower>-1e+16</lower>
          <upper>1e+16</upper>
        </limit>
        <dynamics>
          <spring_reference>0</spring_reference>
          <spring_stiffness>0</spring_stiffness>
          <damping>0.7</damping>
          <friction>0.0</friction>
        </dynamics>
      </axis>
    </joint>

    <link name='wheel_right_link'>
      <pose relative_to='wheel_right_joint'>0 0 0 0 -0 0</pose>
      <inertial>
        <pose>0 0 0 0 -0 0</pose>
        <mass>0.0284989</mass>
        <inertia>
          <ixx>1.11756e-05</ixx>
          <ixy>-4.23698e-11</ixy>
          <ixz>-5.93817e-09</ixz>
          <iyy>1.11924e-05</iyy>
          <iyz>-1.44001e-11</iyz>
          <izz>2.07126e-05</izz>
        </inertia>
      </inertial>
      <collision name='wheel_right_link_collision'>
        <pose>0 0 0 0 -0 0</pose>
        <surface>
          <friction>
            <ode>
              <mu>1.0</mu>
              <mu2>1.0</mu2>
            </ode>
          </friction>
        </surface>
        <geometry>
          <cylinder>
            <length>0.018</length>
            <radius>0.033</radius>
          </cylinder>
        </geometry>
      </collision>
      <visual name='wheel_right_link_visual'>
        <pose>0 0 0 1.57 -0 0</pose>
        <geometry>
          <mesh>
            <scale>0.001 0.001 0.001</scale>
            <uri>model://turtlebot3_description/meshes/wheels/right_tire.stl</uri>
          </mesh>
        </geometry>
        <material>
          <diffuse> 0.145098039 0.156862745 0.164705882 1</diffuse>
          <ambient> 0.145098039 0.156862745 0.164705882 1</ambient>
          <specular>0.145098039 0.156862745 0.164705882 1</specular>
        </material>
      </visual>
    </link>
    
    <link name='caster_back_right_link'>
      <pose>-0.177 -0.064 -0.004 -1.57 0 0</pose>
      <inertial>
        <mass>0.05</mass>
        <inertia>
          <ixx>0.1e-4</ixx>
          <ixy>0.000</ixy>
          <ixz>0.000</ixz>
          <iyy>0.1e-4</iyy>
          <iyz>0.000</iyz>
          <izz>0.1e-4</izz>
        </inertia>
      </inertial>
      <collision name='collision'>
        <geometry>
          <sphere>
            <radius>0.005000</radius>
          </sphere>
        </geometry>
        <surface>
          <contact>
            <ode>
              <soft_cfm>0</soft_cfm>
              <soft_erp>0.2</soft_erp>
              <kp>1e+5</kp>
              <kd>1</kd>
              <max_vel>0.01</max_vel>
              <min_depth>0.001</min_depth>
            </ode>
          </contact>
        </surface>
      </collision>
    </link>

    <joint name='caster_back_right_joint' type='continuous'>
      <parent>sim_base_link</parent>
      <child>caster_back_right_link</child>
      <axis>
        <xyz>0 0 1</xyz>
        <limit>
          <lower>-1e16</lower>
          <upper>1e16</upper>
          <effort>1</effort>
          <velocity>10</velocity>
        </limit>
        <dynamics>
          <damping>0.7</damping>
          <friction>0.1</friction>
        </dynamics>
      </axis>
    </joint>

    <link name='caster_back_left_link'>
      <pose>-0.177 0.064 -0.004 -1.57 0 0</pose>
      <inertial>
        <mass>0.05</mass>
        <inertia>
          <ixx>1e-4</ixx>
          <ixy>0.000</ixy>
          <ixz>0.000</ixz>
          <iyy>1e-4</iyy>
          <iyz>0.000</iyz>
          <izz>1e-4</izz>
        </inertia>
      </inertial>
      <collision name='collision'>
        <geometry>
          <sphere>
            <radius>0.005000</radius>
          </sphere>
        </geometry>
        <surface>
          <contact>
            <ode>
              <soft_cfm>0</soft_cfm>
              <soft_erp>0.2</soft_erp>
              <kp>1e+5</kp>
              <kd>1</kd>
              <max_vel>0.01</max_vel>
              <min_depth>0.001</min_depth>
            </ode>
          </contact>
        </surface>
      </collision>
    </link>

    <joint name='caster_back_left_joint' type='continuous'>
      <parent>sim_base_link</parent>
      <child>caster_back_left_link</child>
      <axis>
        <xyz>0 0 1</xyz>
        <limit>
          <lower>-1e16</lower>
          <upper>1e16</upper>
          <effort>1</effort>
          <velocity>10</velocity>
        </limit>
        <dynamics>
          <damping>0.7</damping>
          <friction>0.1</friction>
        </dynamics>
      </axis>
    </joint>

    <link name="camera_link"/>

    <joint name="camera_joint" type="fixed">
      <parent>sim_base_link</parent>
      <child>camera_link</child>
      <pose>0.064 -0.065 0.094 0 0 0</pose>
      <axis>
        <xyz>0 0 1</xyz>
      </axis>
    </joint>
    
    <link name="camera_rgb_frame">
      <inertial>
        <pose>0.069 -0.047 0.107 0 0 0</pose>
        <inertia>
          <ixx>0.001</ixx>
          <ixy>0.000</ixy>
          <ixz>0.000</ixz>
          <iyy>0.001</iyy>
          <iyz>0.000</iyz>
          <izz>0.001</izz>
        </inertia>
        <mass>0.035</mass>
      </inertial>
      <pose>0.069 -0.047 0.107 0 0 0</pose>
      <sensor name="camera" type="camera">
        <always_on>true</always_on>
        <visualize>true</visualize>
        <update_rate>30</update_rate>
        <camera_info_topic>/sim/camera/rgb/camera_info</camera_info_topic>
        <topic>/sim/camera/rgb/image_raw</topic>
        <ignition_frame_id>camera_rgb_frame</ignition_frame_id>
        <camera name="intel_realsense_r200">
          <horizontal_fov>1.02974</horizontal_fov>
          <image>
            <width>1920</width>
            <height>1080</height>
            <format>R8G8B8</format>
          </image>
          <clip>
            <near>0.02</near>
            <far>300</far>
          </clip>
          <noise>
            <type>gaussian</type>
            <!-- Noise is sampled independently per pixel on each frame.
                  That pixel's noise value is added to each of its color
                  channels, which at that point lie in the range [0,1]. -->
            <mean>0.0</mean>
            <stddev>0.007</stddev>
          </noise>
        </camera>
      </sensor>
    </link>
    
    <joint name="camera_rgb_joint" type="fixed">
      <parent>camera_link</parent>
      <child>camera_rgb_frame</child>
      <pose>0.005 0.018 0.013 0 0 0</pose>
      <axis>
        <xyz>0 0 1</xyz>
      </axis>
    </joint>



    <plugin name="scan" filename="libros_ign_ros2_laser_sensor.so">
      <ros>
        <remapping>scan:=/sim_scan</remapping>  <!-- 반드시 절대경로로 -->
      </ros>
    </plugin>


    <plugin filename="libignition-gazebo-diff-drive-system.so" 
      name="ignition::gazebo::systems::DiffDrive">
      <left_joint>wheel_left_joint</left_joint>
      <right_joint>wheel_right_joint</right_joint>
      <wheel_separation>0.287</wheel_separation>
      <wheel_radius>0.033</wheel_radius>
      <topic>cmd_vel_half</topic>
    </plugin>



    <!-- Differential drive -->
    <plugin filename="libignition-gazebo-diff-drive-system.so" 
      name="ignition::gazebo::systems::DiffDrive">
      <left_joint>wheel_left_joint</left_joint>
      <right_joint>wheel_right_joint</right_joint>
      <wheel_separation>0.287</wheel_separation>
      <wheel_radius>0.033</wheel_radius>
      <topic>cmd_vel_half</topic>
    </plugin>




  </model>
</sdf>

